Workbook

Sheet Synthèse
A1: IFSPA — Gestion de l'écolage
A2: Estimation du reste à faire, en jours-homme (JH) — Institut de Formation Supérieur des Paramédicaux Atsinanana, Toamasina
A3: Établie le 01/10/2026 — Conception et réalisation : Diano ANDRIANTSALAMA
A5: Paramètres
A6: Gestion de projet | B6: 0.1 | C6: Taux demandé : 10 % de la charge de réalisation.
A7: Retours clients | B7: 0.05 | C7: Taux demandé : 5 % de la charge de réalisation.
A8: Tarif journalier (Ar) | C8: Facultatif : à renseigner pour obtenir un montant. Vide, aucun montant n'est calculé.
A10: N° | B10: Lot | C10: Estimation (JH) | D10: Part
A11: 1 | B11: Connexion et cadre de l'application | C11: =SUMIFS(Détail!$F$5:$F$49,Détail!$B$5:$B$49,$B11) -> 0.25 | D11: =IF($C$21=0,0,C11/$C$21) -> 0.038461538
A12: 2 | B12: Paramètres (administrateur) | C12: =SUMIFS(Détail!$F$5:$F$49,Détail!$B$5:$B$49,$B12) -> 0.5 | D12: =IF($C$21=0,0,C12/$C$21) -> 0.076923077
A13: 3 | B13: Étudiants | C13: =SUMIFS(Détail!$F$5:$F$49,Détail!$B$5:$B$49,$B13) -> 0.75 | D13: =IF($C$21=0,0,C13/$C$21) -> 0.11538462
A14: 4 | B14: Écolage et encaissement | C14: =SUMIFS(Détail!$F$5:$F$49,Détail!$B$5:$B$49,$B14) -> 1.5 | D14: =IF($C$21=0,0,C14/$C$21) -> 0.23076923
A15: 5 | B15: Encaissement hors ligne | C15: =SUMIFS(Détail!$F$5:$F$49,Détail!$B$5:$B$49,$B15) -> 1 | D15: =IF($C$21=0,0,C15/$C$21) -> 0.15384615
A16: 6 | B16: Passage en année supérieure et sorties | C16: =SUMIFS(Détail!$F$5:$F$49,Détail!$B$5:$B$49,$B16) -> 0.75 | D16: =IF($C$21=0,0,C16/$C$21) -> 0.11538462
A17: 7 | B17: Tableau de bord | C17: =SUMIFS(Détail!$F$5:$F$49,Détail!$B$5:$B$49,$B17) -> 0.25 | D17: =IF($C$21=0,0,C17/$C$21) -> 0.038461538
A18: 8 | B18: Reprise des données Excel | C18: =SUMIFS(Détail!$F$5:$F$49,Détail!$B$5:$B$49,$B18) -> 0.5 | D18: =IF($C$21=0,0,C18/$C$21) -> 0.076923077
A19: 9 | B19: Mise en production | C19: =SUMIFS(Détail!$F$5:$F$49,Détail!$B$5:$B$49,$B19) -> 0.25 | D19: =IF($C$21=0,0,C19/$C$21) -> 0.038461538
A20: 10 | B20: Recette et formation | C20: =SUMIFS(Détail!$F$5:$F$49,Détail!$B$5:$B$49,$B20) -> 0.75 | D20: =IF($C$21=0,0,C20/$C$21) -> 0.11538462
B21: Sous-total réalisation | C21: =SUM(C11:C20) -> 6.5
B22: Gestion de projet | C22: =C21*$B$6 -> 0.65 | D22: =$B$6 -> 0.1
B23: Retours clients | C23: =C21*$B$7 -> 0.325 | D23: =$B$7 -> 0.05
B24: TOTAL (JH) | C24: =SUM(C21:C23) -> 7.475
B26: Montant total (Ar) | C26: =C24*$B$8 -> 0 | D26: Total JH × tarif journalier
A28: Hypothèses
A29: • Déjà réalisé, exclu de cette estimation : cadrage et spécification, maquettes de tous les écrans, socle technique (base, authentification, données initiales), charte graphique, page d'accueil, galerie, formulaire de contact.
A30: • Charges calées sur la vitesse constatée sur ces fondations (développement assisté par IA, tests de bout en bout automatisés). 1 JH = une journée de travail.
A31: • Hors ligne : uniquement l'écran Encaisser, sans rien installer sur le poste. Les autres écrans demandent Internet.
A32: • Gestion de projet et retours clients sont calculés sur le sous-total de réalisation, aux taux des paramètres ci-dessus.
A33: • Points pouvant faire varier la charge : encaissement hors ligne (tests réels de coupure), délais de validation du client, ticket thermique (modèle d'imprimante), reprise Excel (fichier non encore fourni), version de Node de l'hébergeur.
A34: • Le détail par fonctionnalité, avec description et commentaires, se trouve dans la feuille Détail.

Sheet Détail
A1: IFSPA — Estimation détaillée du reste à faire
A2: En bleu : estimations à ajuster. Les totaux et la feuille Synthèse se recalculent seuls. 1 JH = une journée de travail.
A4: N° | B4: Lot | C4: Fonctionnalité | D4: Description | E4: Commentaires | F4: Estimation (JH)
A5: 1.1 | B5: Connexion et cadre de l'application | C5: Page de connexion | D5: Formulaire de connexion à l'espace de gestion. | F5: 0.1
A6: 1.2 | B6: Connexion et cadre de l'application | C6: Protection des pages et des rôles | D6: Redirection vers la connexion sans session ; contrôle du rôle côté serveur sur chaque action. | E6: Le rôle est vérifié sur le serveur, pas seulement en masquant les boutons. | F6: 0.05
A7: 1.3 | B7: Connexion et cadre de l'application | C7: Cadre de l'application | D7: Menu latéral, menu utilisateur, déconnexion, navigation mobile. | F7: 0.1
A8: 2.1 | B8: Paramètres (administrateur) | C8: Filières | D8: Création et modification (code, nom, durée des études). | E8: IF et SF au départ ; d'autres filières pourront être ajoutées. | F8: 0.1
A9: 2.2 | B9: Paramètres (administrateur) | C9: Années scolaires | D9: Création, année courante, clôture. | F9: 0.1
A10: 2.3 | B10: Paramètres (administrateur) | C10: Tarifs | D10: Droits d'inscription et mensualité par filière, année scolaire et niveau. | E10: Un changement de tarif ne modifie pas les échéances déjà générées. | F10: 0.15
A11: 2.4 | B11: Paramètres (administrateur) | C11: Utilisateurs | D11: Création, rôle, désactivation, réinitialisation du mot de passe. | E11: Deux rôles : admin et user (secrétariat). | F11: 0.15
A12: 3.1 | B12: Étudiants | C12: Matricule automatique | D12: Format FILIÈRE-ANNÉE-NUMÉRO (ex. IF-2026-0001), séquence par filière et année d'entrée. | E12: Ne change jamais, même en cas de redoublement. Testé contre les doublons en cas de créations simultanées. | F12: 0.1
A13: 3.2 | B13: Étudiants | C13: Inscription d'un nouvel étudiant | D13: Fiche d'identité, photo, filière, choix des droits en 1, 2 ou 3 fois ; échéances de l'année générées automatiquement. | E13: Bloquée avec un message clair si le tarif de la classe manque. | F13: 0.2
A14: 3.3 | B14: Étudiants | C14: Liste des étudiants | D14: Recherche par nom ou matricule ; filtres filière, niveau, année, statut, en retard. | F14: 0.15
A15: 3.4 | B15: Étudiants | C15: Fiche étudiant | D15: Identité, parcours année par année, grille d'écolage mois par mois, historique des paiements et reçus. | E15: Pas de tuteur (retiré à la demande du client). | F15: 0.25
A16: 3.5 | B16: Étudiants | C16: Modification d'un étudiant | D16: Mise à jour de l'identité et des coordonnées. | E16: La filière ne se change plus après l'enregistrement. | F16: 0.05
A17: 4.1 | B17: Écolage et encaissement | C17: Calcul de l'écolage | D17: Génération des échéances, répartition des paiements de la plus ancienne à la plus récente, retards et soldes. | E17: Cœur métier couvert par des tests automatisés. Pas de notion d'arriérés : chaque année est suivie pour elle-même. | F17: 0.25
A18: 4.2 | B18: Écolage et encaissement | C18: Droits d'inscription en 1, 2 ou 3 tranches | D18: Tranches exigibles en octobre, novembre et décembre ; parts égales arrondies au millier. | E18: Demande du client. Choix fait à l'inscription, repris l'année suivante. | F18: 0.1
A19: 4.3 | B19: Écolage et encaissement | C19: Paiement partiel (acompte) | D19: Montant reçu libre : le surplus part en acompte sur l'échéance suivante, un montant inférieur paie l'échéance en partie. | E19: Rétabli à la demande du client le 01/10/2026. Trop-perçu au-delà du reste de l'année refusé. | F19: 0.15
A20: 4.4 | B20: Écolage et encaissement | C20: Écran Encaisser | D20: Guichet en 4 gestes : étudiant, échéances à cocher (retards précochés), mode de paiement, un seul bouton qui encaisse et imprime. | E20: Sans fenêtre de confirmation, pensé pour un parent qui attend au guichet. | F20: 0.3
A21: 4.5 | B21: Écolage et encaissement | C21: Modes de paiement | D21: Espèces et Mobile Money (MVola, Orange Money, Airtel Money) avec référence de transaction. | F21: 0.05
A22: 4.6 | B22: Écolage et encaissement | C22: Numérotation des reçus | D22: Numéro unique R-ANNÉE-NUMÉRO, sans trou ni doublon. | F22: 0.05
A23: 4.7 | B23: Écolage et encaissement | C23: Montant en lettres | D23: Conversion en français (« cent cinquante mille ariary »). | F23: 0.05
A24: 4.8 | B24: Écolage et encaissement | C24: Reçu sur ticket thermique | D24: Ticket 80 mm (58 mm en option), monochrome, réimpression, mention ANNULÉ. | E24: Jamais en A4 ni A5, sans QR code (décisions du client). Dépend du modèle d'imprimante de l'institut. | F24: 0.2
A25: 4.9 | B25: Écolage et encaissement | C25: Historique des paiements | D25: Paiements du jour et par période. | F25: 0.1
A26: 4.10 | B26: Écolage et encaissement | C26: Annulation d'un paiement | D26: Réservée à l'administrateur, avec motif, auteur et date. | E26: Aucun paiement n'est supprimé : il reste dans l'historique, marqué annulé. | F26: 0.05
A27: 4.11 | B27: Écolage et encaissement | C27: Impayés | D27: Liste des étudiants en retard (montant, nombre de mois) et export Excel. | F27: 0.1
A28: 4.12 | B28: Écolage et encaissement | C28: Relevé d'écolage | D28: PDF A4 par étudiant : tableau mois par mois pour chaque année, récapitulatif, liste des paiements. | E28: Sert aussi aux parents et aux relances. | F28: 0.1
A29: 5.1 | B29: Encaissement hors ligne | C29: Ouverture de l'écran sans Internet | D29: L'écran Encaisser est gardé en mémoire par le navigateur : il s'ouvre et se recharge même sans connexion. Les autres écrans demandent Internet. | E29: Demande du client. Limité à l'écran Encaisser. | F29: 0.1
A30: 5.2 | B30: Encaissement hors ligne | C30: Copie locale légère | D30: Étudiants actifs, échéances non soldées et tarifs gardés sur le poste. | E30: Pas de copie complète de la base sur le poste. | F30: 0.2
A31: 5.3 | B31: Encaissement hors ligne | C31: File des paiements en attente | D31: Les paiements saisis hors ligne sont gardés sur le poste jusqu'à l'envoi. | E31: Ne pas vider le navigateur tant que des paiements sont en attente. | F31: 0.15
A32: 5.4 | B32: Encaissement hors ligne | C32: Numéros de reçu réservés par poste | D32: Chaque poste réserve un bloc de numéros : le ticket imprimé hors ligne porte son numéro définitif. | E32: Un bloc non utilisé laisse des numéros « non utilisés », listés dans Paiements. | F32: 0.15
A33: 5.5 | B33: Encaissement hors ligne | C33: Synchronisation | D33: Automatique au retour de la connexion puis toutes les 5 minutes, et manuelle ; bandeau d'état. | E33: Un double envoi est sans effet. | F33: 0.15
A34: 5.6 | B34: Encaissement hors ligne | C34: Contrôle au serveur | D34: Chaque paiement est revérifié ; en cas de conflit il est enregistré et signalé « à vérifier » à l'administrateur. | E34: L'argent reçu n'est jamais perdu. | F34: 0.15
A35: 5.7 | B35: Encaissement hors ligne | C35: Session hors ligne | D35: Le poste ne redemande pas le mot de passe avant la synchronisation. | E35: Poste le plus risqué du projet : tests réels de coupure nécessaires. | F35: 0.1
A36: 6.1 | B36: Passage en année supérieure et sorties | C36: Écran de passage par classe | D36: Tous les étudiants sont cochés, on décoche ceux qui ne passent pas (redouble ou abandon) ; avancement par classe. | E36: Écran refait à la demande du client. Une seule confirmation, qui nomme ceux qui ne passent pas. | F36: 0.3
A37: 6.2 | B37: Passage en année supérieure et sorties | C37: Validation d'une classe | D37: Création des inscriptions et des échéances de la nouvelle année, mise à jour des statuts, en une seule opération. | E37: Bloquée si le tarif de la classe cible manque. | F37: 0.2
A38: 6.3 | B38: Passage en année supérieure et sorties | C38: Historique et annulation | D38: L'administrateur annule une opération : l'état d'avant est restauré. | E38: Annulation bloquée si des paiements existent sur les inscriptions créées. | F38: 0.2
A39: 6.4 | B39: Passage en année supérieure et sorties | C39: Sorties | D39: Abandon et exclusion, avec date et motif. | E39: Réservé à l'administrateur. | F39: 0.05
A40: 7.1 | B40: Tableau de bord | C40: Indicateurs | D40: Effectif actif, taux de recouvrement, nombre d'étudiants en retard ; filtre année et filière. | E40: Trois cartes seulement, pas de graphiques (décision du client). | F40: 0.1
A41: 7.2 | B41: Tableau de bord | C41: Tableau récapitulatif | D41: Par filière et niveau : effectif, attendu, encaissé, reste, taux ; 10 derniers paiements. | F41: 0.15
...
